In the Python code provided, I utilized the unittest module to perform two tests. The TestSum class, which inherits from unittest.TestCase, contains these tests. The first one, `test_sum`, correctly tests the built-in `sum` function with a list of numbers `[1, 2, 3]`, and verifies the result is `6`â€”this test is successful. The second test, `test_sum_tuple`, tries to validate the same function, but with a tuple `(1, 2, 2)`. This test fails as the sum of these numbers is `5`, not `6` as the test expects, resulting in an AssertionError with the custom message "Should be 6". The output shows that the total time taken for these tests was negligible, and out of the two tests, one has failed. Interpreting these results, the success of `test_sum` demonstrates that Python's `sum` function operates as expected with a list input. The failure of `test_sum_tuple`, on the other hand, implies there's an error in the test's expected output, not the `sum` function itself. This highlights the necessity for careful accuracy when setting expected outcomes in tests, as incorrect expectations can lead to misleading results.